<mujoco model="darias">
    <compiler angle="radian" meshdir="meshes/" />
    <option timestep="0.0002" tolerance="1e-6"/>
    <size njmax="3000" nconmax="3000" />
    <asset>
        <mesh name="arm_base_convex" file="meshes/arm_base_convex.stl" />
        <mesh name="arm_segment_a_convex" file="meshes/arm_segment_a_convex.stl" />
        <mesh name="arm_segment_b_convex" file="meshes/arm_segment_b_convex.stl" />
        <mesh name="arm_segment_last_convex" file="meshes/arm_segment_last_convex.stl" />
        <mesh name="arm_wrist_convex" file="meshes/arm_wrist_convex.stl" />
        <mesh name="righthandbase" file="meshes/righthandbase.stl" scale="0.001 0.001 0.001" />
        <mesh name="finger_base" file="meshes/finger_base.stl" />
        <mesh name="fore_proximalp" file="meshes/fore_proximalp.stl" scale="0.001 0.001 0.001" />
        <mesh name="fore_middlep" file="meshes/fore_middlep.stl" scale="0.001 0.001 0.001" />
        <mesh name="lefthandbase" file="meshes/lefthandbase.stl" />
    </asset>
    <worldbody>
        <geom size="0.1 0.1 0.75" pos="-0.1 0 0.835" type="box" rgba="0.3 0.3 0.3 1" />
        <geom pos="-0.11 -0.06 1.5" quat="0.353554 0.612372 -0.353553 0.612372" type="mesh" rgba="0 0 0.8 1" mesh="arm_base_convex" />
        <geom pos="-0.11 0.06 1.5" quat="0.612372 -0.353553 0.612372 0.353554" type="mesh" rgba="0 0 0.8 1" mesh="arm_base_convex" />
        <body name="R_1_link" pos="-0.055 -0.155263 1.5" quat="0.353554 0.612372 -0.353553 0.612372">
            <inertial pos="0 0 0.13" quat="0.707107 0.707107 0 0" mass="1" diaginertia="0.00683333 0.00593333 0.0015" />
            <joint name="R_SFE" pos="0 0 0" axis="0 0 1" limited="true" range="-2.96706 2.96706" damping="0.1" />
            <geom quat="0 0 0 1" type="mesh" rgba="0 0 0.8 1" mesh="arm_segment_a_convex" />
            <body name="R_2_link" pos="0 0 0.2">
                <inertial pos="0 0.06 0.07" quat="0.707107 0.707107 0 0" mass="1" diaginertia="0.00683333 0.00593333 0.0015" />
                <joint name="R_SAA" pos="0 0 0" axis="0 -1 0" limited="true" range="-2.0944 2.0944" damping="0.1" />
                <geom pos="0 0 0.2" quat="0 0 1 0" type="mesh" rgba="0 0 0.8 1" mesh="arm_segment_b_convex" />
                <body name="R_3_link" pos="0 0 0.2">
                    <inertial pos="0 0.06 0.13" quat="0.707107 0.707107 0 0" mass="1" diaginertia="0.00683333 0.00593333 0.0015" />
                    <joint name="R_HR" pos="0 0 0" axis="0 0 1" limited="true" range="-2.96706 2.96706" damping="0.1" />
                    <geom type="mesh" rgba="0 0 0.8 1" mesh="arm_segment_a_convex" />
                    <body name="R_4_link" pos="0 0 0.2">
                        <inertial pos="0 -0.06 0.07" quat="0.707107 0.707107 0 0" mass="1" diaginertia="0.00683333 0.00593333 0.0015" />
                        <joint name="R_EB" pos="0 0 0" axis="0 1 0" limited="true" range="-2.0944 2.0944" damping="0.1" />
                        <geom pos="0 0 0.2" quat="0 -1 0 0" type="mesh" rgba="0 0 0.8 1" mesh="arm_segment_b_convex" />
                        <body name="R_5_link" pos="0 0 0.2">
                            <inertial pos="0 0 0.124" quat="0.707107 0.707107 0 0" mass="1" diaginertia="0.00632533 0.00542533 0.0015" />
                            <joint name="R_WR" pos="0 0 0" axis="0 0 1" limited="true" range="-2.96706 2.96706" damping="0.1" />
                            <geom quat="0 0 0 1" type="mesh" rgba="0 0 0.8 1" mesh="arm_segment_last_convex" />
                            <body name="R_6_link" pos="0 0 0.19">
                                <inertial pos="0 0 0.0625" mass="1" diaginertia="0.00260417 0.00260417 0.00260417" />
                                <joint name="R_WFE" pos="0 0 0" axis="0 -1 0" limited="true" range="-2.0944 2.0944" damping="0.1" />
                                <geom quat="0 0 0 1" type="mesh" rgba="0.953 0.996 0.694 1" mesh="arm_wrist_convex" />
                                <body name="right_endeffector_link" pos="0 0 0.078">
                                    <inertial pos="0.000665605 0.00133386 0.067" quat="-0.0245828 0.702769 -0.0197878 0.710718" mass="1.5" diaginertia="0.00436661 0.00407968 0.00357047" />
                                    <joint name="R_WAA" pos="0 0 0" axis="0 0 1" limited="true" range="-2.96706 2.96706" damping="0.1" />
                                    <geom pos="0.00701592 -0.0199944 0.025" quat="0.707388 0.706825 0 0" type="mesh" rgba="0.953 0.996 0.694 1" mesh="righthandbase" />
                                    <body name="R_SMS_link" pos="-0.0433955 -0.00100613 0.0950435" quat="0.508308 0.508699 -0.491147 0.491552">
                                        <inertial pos="0.004 0 0" quat="0.707107 0.707107 0 0" mass="0.1" diaginertia="2.24083e-05 1.85417e-05 1.42833e-05" />
                                        <joint name="R_SMS" pos="0 0 0" axis="0 0 1" limited="true" range="-0.261 0.2618" damping="0.005" />
                                        <geom type="mesh" rgba="0.953 0.996 0.694 1" mesh="finger_base" />
                                        <body name="R_SMP_link" pos="0 0 0" quat="0.707107 0.707107 0 0">
                                            <inertial pos="0.035 -0.02 0" quat="0.707107 0 0 0.707107" mass="0.1" diaginertia="7.00417e-05 6.68333e-05 2.48083e-05" />
                                            <joint name="R_SMP" pos="0 0 0" axis="0 0 1" limited="true" range="0.087 1.4835" damping="0.005" />
                                            <geom pos="-0.085 0.015 -0.03" quat="0.500398 -0.499602 -0.5 -0.5" type="mesh" rgba="0.953 0.996 0.694 1" mesh="fore_proximalp" />
                                            <body name="R_SMD_link" pos="0.055 0 0">
                                                <inertial pos="0.015 -0.01 0" mass="0.1" diaginertia="3.00333e-05 2.90667e-05 1.40333e-05" />
                                                <joint name="R_SMD" pos="0 0 0" axis="0 0 1" limited="true" range="0.087 1.1345" damping="0.005" />
                                                <geom pos="-0.14 0.015 -0.03" quat="0.505373 -0.494577 -0.504971 -0.494971" type="mesh" rgba="0.953 0.996 0.694 1" mesh="fore_middlep" />
                                            </body>
                                        </body>
                                    </body>
                                    <body name="R_RIS_link" pos="-0.0168021 0.0025165 0.114044" quat="0.508308 0.508699 -0.491147 0.491552">
                                        <inertial pos="0.004 0 0" quat="0.707107 0.707107 0 0" mass="0.1" diaginertia="2.24083e-05 1.85417e-05 1.42833e-05" />
                                        <joint name="R_RIS" pos="0 0 0" axis="0 0 1" limited="true" range="-0.261 0.2618" damping="0.005" />
                                        <geom type="mesh" rgba="0.953 0.996 0.694 1" mesh="finger_base" />
                                        <body name="R_RIP_link" pos="0 0 0" quat="0.707107 0.707107 0 0">
                                            <inertial pos="0.035 -0.02 0" quat="0.707107 0 0 0.707107" mass="0.1" diaginertia="7.00417e-05 6.68333e-05 2.48083e-05" />
                                            <joint name="R_RIP" pos="0 0 0" axis="0 0 1" limited="true" range="0.087 1.4835" damping="0.005" />
                                            <geom pos="-0.085 0.015 -0.03" quat="0.500398 -0.499602 -0.5 -0.5" type="mesh" rgba="0.953 0.996 0.694 1" mesh="fore_proximalp" />
                                            <body name="R_RID_link" pos="0.055 0 0">
                                                <inertial pos="0.015 -0.01 0" mass="0.1" diaginertia="3.00333e-05 2.90667e-05 1.40333e-05" />
                                                <joint name="R_RID" pos="0 0 0" axis="0 0 1" limited="true" range="0.087 1.1345" damping="0.005" />
                                                <geom pos="-0.14 0.015 -0.03" quat="0.505373 -0.494577 -0.504971 -0.494971" type="mesh" rgba="0.953 0.996 0.694 1" mesh="fore_middlep" />
                                            </body>
                                        </body>
                                    </body>
                                    <body name="R_MIS_link" pos="0.00979812 0.00253768 0.116744" quat="0.508308 0.508699 -0.491147 0.491552">
                                        <inertial pos="0.004 0 0" quat="0.707107 0.707107 0 0" mass="0.1" diaginertia="2.24083e-05 1.85417e-05 1.42833e-05" />
                                        <joint name="R_MIS" pos="0 0 0" axis="0 0 1" limited="true" range="-0.261 0.2618" damping="0.005" />
                                        <geom type="mesh" rgba="0.953 0.996 0.694 1" mesh="finger_base" />
                                        <body name="R_MIP_link" pos="0 0 0" quat="0.707107 0.707107 0 0">
                                            <inertial pos="0.035 -0.02 0" quat="0.707107 0 0 0.707107" mass="0.1" diaginertia="7.00417e-05 6.68333e-05 2.48083e-05" />
                                            <joint name="R_MIP" pos="0 0 0" axis="0 0 1" limited="true" range="0.087 1.4835" damping="0.005" />
                                            <geom pos="-0.085 0.015 -0.03" quat="0.500398 -0.499602 -0.5 -0.5" type="mesh" rgba="0.953 0.996 0.694 1" mesh="fore_proximalp" />
                                            <body name="R_MID_link" pos="0.055 0 0">
                                                <inertial pos="0.015 -0.01 0" mass="0.1" diaginertia="3.00333e-05 2.90667e-05 1.40333e-05" />
                                                <joint name="R_MID" pos="0 0 0" axis="0 0 1" limited="true" range="0.087 1.1345" damping="0.005" />
                                                <geom pos="-0.14 0.015 -0.03" quat="0.505373 -0.494577 -0.504971 -0.494971" type="mesh" rgba="0.953 0.996 0.694 1" mesh="fore_middlep" />
                                            </body>
                                        </body>
                                    </body>
                                    <body name="R_INS_link" pos="0.0367981 0.00255919 0.108744" quat="0.508308 0.508699 -0.491147 0.491552">
                                        <inertial pos="0.004 0 0" quat="0.707107 0.707107 0 0" mass="0.1" diaginertia="2.24083e-05 1.85417e-05 1.42833e-05" />
                                        <joint name="R_INS" pos="0 0 0" axis="0 0 1" limited="true" range="-0.261 0.2618" damping="0.005" />
                                        <geom type="mesh" rgba="0.953 0.996 0.694 1" mesh="finger_base" />
                                        <body name="R_INP_link" pos="0 0 0" quat="0.707107 0.707107 0 0">
                                            <inertial pos="0.035 -0.02 0" quat="0.707107 0 0 0.707107" mass="0.1" diaginertia="7.00417e-05 6.68333e-05 2.48083e-05" />
                                            <joint name="R_INP" pos="0 0 0" axis="0 0 1" limited="true" range="0.087 1.4835" damping="0.005" />
                                            <geom pos="-0.085 0.015 -0.03" quat="0.500398 -0.499602 -0.5 -0.5" type="mesh" rgba="0.953 0.996 0.694 1" mesh="fore_proximalp" />
                                            <body name="R_IND_link" pos="0.055 0 0">
                                                <inertial pos="0.015 -0.01 0" mass="0.1" diaginertia="3.00333e-05 2.90667e-05 1.40333e-05" />
                                                <joint name="R_IND" pos="0 0 0" axis="0 0 1" limited="true" range="0.087 1.1345" damping="0.005" />
                                                <geom pos="-0.14 0.015 -0.03" quat="0.505373 -0.494577 -0.504971 -0.494971" type="mesh" rgba="0.953 0.996 0.694 1" mesh="fore_middlep" />
                                            </body>
                                        </body>
                                    </body>
                                    <body name="R_THS_link" pos="0.0445944 -0.0625336 0.0800446" quat="0.786357 -0.213643 -0.409349 -0.410406">
                                        <inertial pos="0.004 0 0" quat="0.707107 0.707107 0 0" mass="0.1" diaginertia="2.24083e-05 1.85417e-05 1.42833e-05" />
                                        <joint name="R_THS" pos="0 0 0" axis="0 0 1" limited="true" range="-0.261 0.2618" damping="0.005" />
                                        <geom type="mesh" rgba="0.953 0.996 0.694 1" mesh="finger_base" />
                                        <body name="R_THP_link" pos="0 0 0" quat="0.707107 0.707107 0 0">
                                            <inertial pos="0.035 -0.02 0" quat="0.707107 0 0 0.707107" mass="0.1" diaginertia="7.00417e-05 6.68333e-05 2.48083e-05" />
                                            <joint name="R_THP" pos="0 0 0" axis="0 0 1" limited="true" range="0.087 1.4835" damping="0.005" />
                                            <geom pos="-0.085 0.015 -0.03" quat="0.500398 -0.499602 -0.5 -0.5" type="mesh" rgba="0.953 0.996 0.694 1" mesh="fore_proximalp" />
                                            <body name="R_THD_link" pos="0.055 0 0">
                                                <inertial pos="0.015 -0.01 0" mass="0.1" diaginertia="3.00333e-05 2.90667e-05 1.40333e-05" />
                                                <joint name="R_THD" pos="0 0 0" axis="0 0 1" limited="true" range="0.087 1.1345" damping="0.005" />
                                                <geom pos="-0.14 0.015 -0.03" quat="0.505373 -0.494577 -0.504971 -0.494971" type="mesh" rgba="0.953 0.996 0.694 1" mesh="fore_middlep" />
                                            </body>
                                        </body>
                                    </body>
                                </body>
                            </body>
                        </body>
                    </body>
                </body>
            </body>
        </body>
        <body name="L_1_link" pos="-0.055 0.155263 1.5" quat="0.612372 -0.353553 0.612372 0.353554">
            <inertial pos="0 0 0.13" quat="0.707107 0.707107 0 0" mass="1" diaginertia="0.00683333 0.00593333 0.0015" />
            <joint name="L_SFE" pos="0 0 0" axis="0 0 1" limited="true" range="-2.96706 2.96706" damping="0.1" />
            <geom quat="0 0 0 1" type="mesh" rgba="0 0 0.8 1" mesh="arm_segment_a_convex" />
            <body name="L_2_link" pos="0 0 0.2">
                <inertial pos="0 0.06 0.07" quat="0.707107 0.707107 0 0" mass="1" diaginertia="0.00683333 0.00593333 0.0015" />
                <joint name="L_SAA" pos="0 0 0" axis="0 -1 0" limited="true" range="-2.0944 2.0944" damping="0.1" />
                <geom pos="0 0 0.2" quat="0 0 1 0" type="mesh" rgba="0 0 0.8 1" mesh="arm_segment_b_convex" />
                <body name="L_3_link" pos="0 0 0.2">
                    <inertial pos="0 0.06 0.13" quat="0.707107 0.707107 0 0" mass="1" diaginertia="0.00683333 0.00593333 0.0015" />
                    <joint name="L_HR" pos="0 0 0" axis="0 0 1" limited="true" range="-2.96706 2.96706" damping="0.1" />
                    <geom type="mesh" rgba="0 0 0.8 1" mesh="arm_segment_a_convex" />
                    <body name="L_4_link" pos="0 0 0.2">
                        <inertial pos="0 -0.06 0.07" quat="0.707107 0.707107 0 0" mass="1" diaginertia="0.00683333 0.00593333 0.0015" />
                        <joint name="L_EB" pos="0 0 0" axis="0 1 0" limited="true" range="-2.0944 2.0944" damping="0.1" />
                        <geom pos="0 0 0.2" quat="0 -1 0 0" type="mesh" rgba="0 0 0.8 1" mesh="arm_segment_b_convex" />
                        <body name="L_5_link" pos="0 0 0.2">
                            <inertial pos="0 0 0.124" quat="0.707107 0.707107 0 0" mass="1" diaginertia="0.00632533 0.00542533 0.0015" />
                            <joint name="L_WR" pos="0 0 0" axis="0 0 1" limited="true" range="-2.96706 2.96706" damping="0.1" />
                            <geom quat="0 0 0 1" type="mesh" rgba="0 0 0.8 1" mesh="arm_segment_last_convex" />
                            <body name="L_6_link" pos="0 0 0.19">
                                <inertial pos="0 0 0.0625" mass="1" diaginertia="0.00260417 0.00260417 0.00260417" />
                                <joint name="L_WFE" pos="0 0 0" axis="0 -1 0" limited="true" range="-2.0944 2.0944" damping="0.1" />
                                <geom quat="0 0 0 1" type="mesh" rgba="0.953 0.996 0.694 1" mesh="arm_wrist_convex" />
                                <body name="left_endeffector_link" pos="0 0 0.078">
                                    <inertial pos="0.000665605 0.00133386 0.067" quat="-0.0245828 0.702769 -0.0197878 0.710718" mass="1.5" diaginertia="0.00436661 0.00407968 0.00357047" />
                                    <joint name="L_WAA" pos="0 0 0" axis="0 0 1" limited="true" range="-2.0944 2.0944" damping="0.1" />
                                    <geom pos="-0.00698407 -0.0200056 0.025" quat="0.707388 0.706825 0 0" type="mesh" rgba="0.953 0.996 0.694 1" mesh="lefthandbase" />
                                    <body name="L_SMS_link" pos="0.0433971 -0.000937013 0.0950435" quat="0.508308 0.508699 -0.491147 0.491552">
                                        <inertial pos="0.004 0 0" quat="0.707107 0.707107 0 0" mass="0.1" diaginertia="2.24083e-05 1.85417e-05 1.42833e-05" />
                                        <joint name="L_SMS" pos="0 0 0" axis="0 0 1" limited="true" range="-0.261 0.2618" damping="0.005" />
                                        <geom type="mesh" rgba="0.953 0.996 0.694 1" mesh="finger_base" />
                                        <body name="L_SMP_link" pos="0 0 0" quat="0.707107 0.707107 0 0">
                                            <inertial pos="0.035 -0.02 0" quat="0.707107 0 0 0.707107" mass="0.1" diaginertia="7.00417e-05 6.68333e-05 2.48083e-05" />
                                            <joint name="L_SMP" pos="0 0 0" axis="0 0 1" limited="true" range="0.087 1.4835" damping="0.005" />
                                            <geom pos="-0.085 0.015 -0.03" quat="0.500398 -0.499602 -0.5 -0.5" type="mesh" rgba="0.953 0.996 0.694 1" mesh="fore_proximalp" />
                                            <body name="L_SMD_link" pos="0.055 0 0">
                                                <inertial pos="0.015 -0.01 0" mass="0.1" diaginertia="3.00333e-05 2.90667e-05 1.40333e-05" />
                                                <joint name="L_SMD" pos="0 0 0" axis="0 0 1" limited="true" range="0.087 1.1345" damping="0.005" />
                                                <geom pos="-0.14 0.015 -0.03" quat="0.505373 -0.494577 -0.504971 -0.494971" type="mesh" rgba="0.953 0.996 0.694 1" mesh="fore_middlep" />
                                            </body>
                                        </body>
                                    </body>
                                    <body name="L_RIS_link" pos="0.0167981 0.00254326 0.114044" quat="0.508308 0.508699 -0.491147 0.491552">
                                        <inertial pos="0.004 0 0" quat="0.707107 0.707107 0 0" mass="0.1" diaginertia="2.24083e-05 1.85417e-05 1.42833e-05" />
                                        <joint name="L_RIS" pos="0 0 0" axis="0 0 1" limited="true" range="-0.261 0.2618" damping="0.005" />
                                        <geom type="mesh" rgba="0.953 0.996 0.694 1" mesh="finger_base" />
                                        <body name="L_RIP_link" pos="0 0 0" quat="0.707107 0.707107 0 0">
                                            <inertial pos="0.035 -0.02 0" quat="0.707107 0 0 0.707107" mass="0.1" diaginertia="7.00417e-05 6.68333e-05 2.48083e-05" />
                                            <joint name="L_RIP" pos="0 0 0" axis="0 0 1" limited="true" range="0.087 1.4835" damping="0.005" />
                                            <geom pos="-0.085 0.015 -0.03" quat="0.500398 -0.499602 -0.5 -0.5" type="mesh" rgba="0.953 0.996 0.694 1" mesh="fore_proximalp" />
                                            <body name="L_RID_link" pos="0.055 0 0">
                                                <inertial pos="0.015 -0.01 0" mass="0.1" diaginertia="3.00333e-05 2.90667e-05 1.40333e-05" />
                                                <joint name="L_RID" pos="0 0 0" axis="0 0 1" limited="true" range="0.087 1.1345" damping="0.005" />
                                                <geom pos="-0.14 0.015 -0.03" quat="0.505373 -0.494577 -0.504971 -0.494971" type="mesh" rgba="0.953 0.996 0.694 1" mesh="fore_middlep" />
                                            </body>
                                        </body>
                                    </body>
                                    <body name="L_MIS_link" pos="-0.0100029 0.00369204 0.119" quat="0.508308 0.508699 -0.491147 0.491552">
                                        <inertial pos="0.004 0 0" quat="0.707107 0.707107 0 0" mass="0.1" diaginertia="2.24083e-05 1.85417e-05 1.42833e-05" />
                                        <joint name="L_MIS" pos="0 0 0" axis="0 0 1" limited="true" range="-0.261 0.2618" damping="0.005" />
                                        <geom type="mesh" rgba="0.953 0.996 0.694 1" mesh="finger_base" />
                                        <body name="L_MIP_link" pos="0 0 0" quat="0.707107 0.707107 0 0">
                                            <inertial pos="0.035 -0.02 0" quat="0.707107 0 0 0.707107" mass="0.1" diaginertia="7.00417e-05 6.68333e-05 2.48083e-05" />
                                            <joint name="L_MIP" pos="0 0 0" axis="0 0 1" limited="true" range="0.087 1.4835" damping="0.005" />
                                            <geom pos="-0.085 0.015 -0.03" quat="0.500398 -0.499602 -0.5 -0.5" type="mesh" rgba="0.953 0.996 0.694 1" mesh="fore_proximalp" />
                                            <body name="L_MID_link" pos="0.055 0 0">
                                                <inertial pos="0.015 -0.01 0" mass="0.1" diaginertia="3.00333e-05 2.90667e-05 1.40333e-05" />
                                                <joint name="L_MID" pos="0 0 0" axis="0 0 1" limited="true" range="0.087 1.1345" damping="0.005" />
                                                <geom pos="-0.14 0.015 -0.03" quat="0.505373 -0.494577 -0.504971 -0.494971" type="mesh" rgba="0.953 0.996 0.694 1" mesh="fore_middlep" />
                                            </body>
                                        </body>
                                    </body>
                                    <body name="L_INS_link" pos="-0.0368021 0.00250058 0.108744" quat="0.508308 0.508699 -0.491147 0.491552">
                                        <inertial pos="0.004 0 0" quat="0.707107 0.707107 0 0" mass="0.1" diaginertia="2.24083e-05 1.85417e-05 1.42833e-05" />
                                        <joint name="L_INS" pos="0 0 0" axis="0 0 1" limited="true" range="-0.261 0.2618" damping="0.005" />
                                        <geom type="mesh" rgba="0.953 0.996 0.694 1" mesh="finger_base" />
                                        <body name="L_INP_link" pos="0 0 0" quat="0.707107 0.707107 0 0">
                                            <inertial pos="0.035 -0.02 0" quat="0.707107 0 0 0.707107" mass="0.1" diaginertia="7.00417e-05 6.68333e-05 2.48083e-05" />
                                            <joint name="L_INP" pos="0 0 0" axis="0 0 1" limited="true" range="0.087 1.4835" damping="0.005" />
                                            <geom pos="-0.085 0.015 -0.03" quat="0.500398 -0.499602 -0.5 -0.5" type="mesh" rgba="0.953 0.996 0.694 1" mesh="fore_proximalp" />
                                            <body name="L_IND_link" pos="0.055 0 0">
                                                <inertial pos="0.015 -0.01 0" mass="0.1" diaginertia="3.00333e-05 2.90667e-05 1.40333e-05" />
                                                <joint name="L_IND" pos="0 0 0" axis="0 0 1" limited="true" range="0.087 1.1345" damping="0.005" />
                                                <geom pos="-0.14 0.015 -0.03" quat="0.505373 -0.494577 -0.504971 -0.494971" type="mesh" rgba="0.953 0.996 0.694 1" mesh="fore_middlep" />
                                            </body>
                                        </body>
                                    </body>
                                    <body name="L_THS_link" pos="-0.0444947 -0.0626045 0.0800446" quat="0.411032 -0.409179 -0.213969 -0.78603">
                                        <inertial pos="0.004 0 0" quat="0.707107 0.707107 0 0" mass="0.1" diaginertia="2.24083e-05 1.85417e-05 1.42833e-05" />
                                        <joint name="L_THS" pos="0 0 0" axis="0 0 1" limited="true" range="-0.261 0.2618" damping="0.005" />
                                        <geom type="mesh" rgba="0.953 0.996 0.694 1" mesh="finger_base" />
                                        <body name="L_THP_link" pos="0 0 0" quat="0.707107 0.707107 0 0">
                                            <inertial pos="0.035 -0.02 0" quat="0.707107 0 0 0.707107" mass="0.1" diaginertia="7.00417e-05 6.68333e-05 2.48083e-05" />
                                            <joint name="L_THP" pos="0 0 0" axis="0 0 1" limited="true" range="0.087 1.4835" damping="0.005" />
                                            <geom pos="-0.085 0.015 -0.03" quat="0.500398 -0.499602 -0.5 -0.5" type="mesh" rgba="0.953 0.996 0.694 1" mesh="fore_proximalp" />
                                            <body name="L_THD_link" pos="0.055 0 0">
                                                <inertial pos="0.015 -0.01 0" mass="0.1" diaginertia="3.00333e-05 2.90667e-05 1.40333e-05" />
                                                <joint name="L_THD" pos="0 0 0" axis="0 0 1" limited="true" range="0.087 1.1345" damping="0.005" />
                                                <geom pos="-0.14 0.015 -0.03" quat="0.505373 -0.494577 -0.504971 -0.494971" type="mesh" rgba="0.953 0.996 0.694 1" mesh="fore_middlep" />
                                            </body>
                                        </body>
                                    </body>
                                </body>
                            </body>
                        </body>
                    </body>
                </body>
            </body>
        </body>
    </worldbody>
</mujoco>
