<mujoco model="darias">
    <compiler angle="radian" meshdir="meshes/" />
    <option timestep="0.0002" tolerance="1e-6"/>
    <size njmax="3000" nconmax="3000" />
    <actuator>
<!--right arm-->
        <motor ctrllimited="true" ctrlrange="-80.0 80.0" joint="R_SFE" name="torq_RSFE"/>
        <motor ctrllimited="true" ctrlrange="-80.0 80.0" joint="R_SAA" name="torq_RSAA"/>
        <motor ctrllimited="true" ctrlrange="-80.0 80.0" joint="R_HR" name="torq_RHR"/>
        <motor ctrllimited="true" ctrlrange="-80.0 80.0" joint="R_EB" name="torq_REB"/>
        <motor ctrllimited="true" ctrlrange="-80.0 80.0" joint="R_WR" name="torq_RWR"/>
        <motor ctrllimited="true" ctrlrange="-12.0 12.0" joint="R_WFE" name="torq_RWFE"/>
        <motor ctrllimited="true" ctrlrange="-12.0 12.0" joint="R_WAA" name="torq_RWAA"/>
<!-- right hand-->
	<position ctrllimited="true" ctrlrange="-3.1416 3.1416" joint="R_SMS" kp="800" name="right_small_joint_1" forcelimited="true" forcerange="-20 20"/>
        <position ctrllimited="true" ctrlrange="-3.1416 3.1416" joint="R_SMP" kp="500" name="right_small_joint_2" forcelimited="true" forcerange="-20 20"/>
        <position ctrllimited="true" ctrlrange="-3.1416 3.1416" joint="R_SMD" kp="50" name="right_small_joint_3" forcelimited="true" forcerange="-20 20"/>
       
        <position ctrllimited="true" ctrlrange="-3.1416 3.1416" joint="R_RIS" kp="600" name="right_ringfinger_joint_1" forcelimited="true" forcerange="-20 20"/>
        <position ctrllimited="true" ctrlrange="-3.1416 3.1416" joint="R_RIP" kp="500" name="right_ringfinger_joint_2" forcelimited="true" forcerange="-20 20"/>
        <position ctrllimited="true" ctrlrange="-3.1416 3.1416" joint="R_RID" kp="50" name="right_ringfinger_joint_3" forcelimited="true" forcerange="-20 20"/>

        <position ctrllimited="true" ctrlrange="-3.1416 3.1416" joint="R_MIS" kp="600" name="right_middle_joint_1" forcelimited="true" forcerange="-20 20"/>
        <position ctrllimited="true" ctrlrange="-3.1416 3.1416" joint="R_MIP" kp="500" name="right_middle_joint_2" forcelimited="true" forcerange="-20 20"/>
        <position ctrllimited="true" ctrlrange="-3.1416 3.1416" joint="R_MID" kp="50" name="right_middle_joint_3" forcelimited="true" forcerange="-20 20"/>

  	<position ctrllimited="true" ctrlrange="-3.1416 3.1416" joint="R_INS" kp="600" name="right_indexfinger_joint_1" forcelimited="true" forcerange="-20 20"/>
        <position ctrllimited="true" ctrlrange="-3.1416 3.1416" joint="R_INP" kp="300" name="right_indexfinger_joint_2" forcelimited="true" forcerange="-20 20"/>
        <position ctrllimited="true" ctrlrange="-3.1416 3.1416" joint="R_IND" kp="50" name="right_indexfinger_joint_3" forcelimited="true" forcerange="-20 20"/>

  	<position ctrllimited="true" ctrlrange="-3.1416 3.1416" joint="R_THS" kp="800" name="right_thumb_joint_1" forcelimited="true" forcerange="-20 20"/>
        <position ctrllimited="true" ctrlrange="-3.1416 3.1416" joint="R_THP" kp="300" name="right_thumb_joint_2" forcelimited="true" forcerange="-20 20"/>
        <position ctrllimited="true" ctrlrange="-3.1416 3.1416" joint="R_THD" kp="50" name="right_thumb_joint_3" forcelimited="true" forcerange="-20 20"/>

<!-- left arm-->
	<motor ctrllimited="true" ctrlrange="-80.0 80.0" joint="L_SFE" name="torq_LSFE"/>
        <motor ctrllimited="true" ctrlrange="-80.0 80.0" joint="L_SAA" name="torq_LSAA"/>
        <motor ctrllimited="true" ctrlrange="-80.0 80.0" joint="L_HR" name="torq_LHR"/>
        <motor ctrllimited="true" ctrlrange="-80.0 80.0" joint="L_EB" name="torq_LEB"/>
        <motor ctrllimited="true" ctrlrange="-80.0 80.0" joint="L_WR" name="torq_LWR"/>
        <motor ctrllimited="true" ctrlrange="-12.0 12.0" joint="L_WFE" name="torq_LWFE"/>
        <motor ctrllimited="true" ctrlrange="-12.0 12.0" joint="L_WAA" name="torq_LWAA"/>
<!-- left hand-->
	    <position ctrllimited="true" ctrlrange="-3.1416 3.1416" joint="L_SMS" kp="800" name="left_small_joint_1" forcelimited="true" forcerange="-20 20"/>
        <position ctrllimited="true" ctrlrange="-3.1416 3.1416" joint="L_SMP" kp="500" name="left_small_joint_2" forcelimited="true" forcerange="-20 20"/>
        <position ctrllimited="true" ctrlrange="-3.1416 3.1416" joint="L_SMD" kp="50" name="left_small_joint_3" forcelimited="true" forcerange="-20 20"/>
       
        <position ctrllimited="true" ctrlrange="-3.1416 3.1416" joint="L_RIS" kp="600" name="left_ringfinger_joint_1" forcelimited="true" forcerange="-20 20"/>
        <position ctrllimited="true" ctrlrange="-3.1416 3.1416" joint="L_RIP" kp="500" name="left_ringfinger_joint_2" forcelimited="true" forcerange="-20 20"/>
        <position ctrllimited="true" ctrlrange="-3.1416 3.1416" joint="L_RID" kp="50" name="left_ringfinger_joint_3" forcelimited="true" forcerange="-20 20"/>

        <position ctrllimited="true" ctrlrange="-3.1416 3.1416" joint="L_MIS" kp="600" name="left_middle_joint_1" forcelimited="true" forcerange="-20 20"/>
        <position ctrllimited="true" ctrlrange="-3.1416 3.1416" joint="L_MIP" kp="500" name="left_middle_joint_2" forcelimited="true" forcerange="-20 20"/>
        <position ctrllimited="true" ctrlrange="-3.1416 3.1416" joint="L_MID" kp="50" name="left_middle_joint_3" forcelimited="true" forcerange="-20 20"/>

  	<position ctrllimited="true" ctrlrange="-3.1416 3.1416" joint="L_INS" kp="600" name="left_indexfinger_joint_1" forcelimited="true" forcerange="-20 20"/>
        <position ctrllimited="true" ctrlrange="-3.1416 3.1416" joint="L_INP" kp="300" name="left_indexfinger_joint_2" forcelimited="true" forcerange="-20 20"/>
        <position ctrllimited="true" ctrlrange="-3.1416 3.1416" joint="L_IND" kp="50" name="left_indexfinger_joint_3" forcelimited="true" forcerange="-20 20"/>

  	<position ctrllimited="true" ctrlrange="-3.1416 3.1416" joint="L_THS" kp="800" name="left_thumb_joint_1" forcelimited="true" forcerange="-20 20"/>
        <position ctrllimited="true" ctrlrange="-3.1416 3.1416" joint="L_THP" kp="300" name="left_thumb_joint_2" forcelimited="true" forcerange="-20 20"/>
        <position ctrllimited="true" ctrlrange="-3.1416 3.1416" joint="L_MID" kp="50" name="left_thumb_joint_3" forcelimited="true" forcerange="-20 20"/>

    </actuator>
   
   <asset>
        <mesh name="arm_base_convex" file="meshes/arm_base_convex.stl" />
        <mesh name="arm_segment_a_convex" file="meshes/arm_segment_a_convex.stl" />
        <mesh name="arm_segment_b_convex" file="meshes/arm_segment_b_convex.stl" />
        <mesh name="arm_segment_last_convex" file="meshes/arm_segment_last_convex.stl" />
        <mesh name="arm_wrist_convex" file="meshes/arm_wrist_convex.stl" />
        <mesh name="righthandbase" file="meshes/righthandbase.stl" scale="0.001 0.001 0.001" />
        <mesh name="finger_base" file="meshes/finger_base.stl" />
        <mesh name="fore_distalp" file="meshes/fore_distalp.stl" scale="0.001 0.001 0.001" />
        <mesh name="fore_proximalp" file="meshes/fore_proximalp.stl" scale="0.001 0.001 0.001" />
        <mesh name="fore_middlep" file="meshes/fore_middlep.stl" scale="0.001 0.001 0.001" />
        <mesh name="lefthandbase" file="meshes/lefthandbase.stl" />
    </asset>
    <worldbody>
        <geom size="0.1 0.1 0.75" pos="-0.1 0 0.835" type="box" rgba="0.3 0.3 0.3 1" />
        <!--<geom pos="-0.11 -0.06 1.5" quat="0.353554 0.612372 -0.353553 0.612372" type="mesh" rgba="0 0 0.8 1" mesh="arm_base_convex" />
        <geom pos="-0.11 0.06 1.5" quat="0.612372 -0.353553 0.612372 0.353554" type="mesh" rgba="0 0 0.8 1" mesh="arm_base_convex" />-->
        <body name="R_1_link" pos="-0.055 -0.155263 1.5" quat="0.353554 0.612372 -0.353553 0.612372">
            <inertial pos="0 0 0.13" quat="0.707107 0.707107 0 0" mass="1" diaginertia="0.00683333 0.00593333 0.0015" />
            <joint name="R_SFE" pos="0 0 0" axis="0 0 1" limited="true" range="-2.96706 2.96706" damping="0.1" />
            <geom quat="0 0 0 1" type="mesh" rgba="0 0 0.8 1" mesh="arm_segment_a_convex" />
            <body name="R_2_link" pos="0 0 0.2">
                <inertial pos="0 0.06 0.07" quat="0.707107 0.707107 0 0" mass="1" diaginertia="0.00683333 0.00593333 0.0015" />
                <joint name="R_SAA" pos="0 0 0" axis="0 -1 0" limited="true" range="-2.0944 2.0944" damping="0.1" />
                <geom pos="0 0 0.2" quat="0 0 1 0" type="mesh" rgba="0 0 0.8 1" mesh="arm_segment_b_convex" />
                <body name="R_3_link" pos="0 0 0.2">
                    <inertial pos="0 0.06 0.13" quat="0.707107 0.707107 0 0" mass="1" diaginertia="0.00683333 0.00593333 0.0015" />
                    <joint name="R_HR" pos="0 0 0" axis="0 0 1" limited="true" range="-2.96706 2.96706" damping="0.1" />
                    <geom type="mesh" rgba="0 0 0.8 1" mesh="arm_segment_a_convex" />
                    <body name="R_4_link" pos="0 0 0.2">
                        <inertial pos="0 -0.06 0.07" quat="0.707107 0.707107 0 0" mass="1" diaginertia="0.00683333 0.00593333 0.0015" />
                        <joint name="R_EB" pos="0 0 0" axis="0 1 0" limited="true" range="-2.0944 2.0944" damping="0.1" />
                        <geom pos="0 0 0.2" quat="0 -1 0 0" type="mesh" rgba="0 0 0.8 1" mesh="arm_segment_b_convex" />
                        <body name="R_5_link" pos="0 0 0.2">
                            <inertial pos="0 0 0.124" quat="0.707107 0.707107 0 0" mass="1" diaginertia="0.00632533 0.00542533 0.0015" />
                            <joint name="R_WR" pos="0 0 0" axis="0 0 1" limited="true" range="-2.96706 2.96706" damping="0.1" />
                            <geom quat="0 0 0 1" type="mesh" rgba="0 0 0.8 1" mesh="arm_segment_last_convex" />
                            <body name="R_6_link" pos="0 0 0.19">
                                <inertial pos="0 0 0.0625" mass="1" diaginertia="0.00260417 0.00260417 0.00260417" />
                                <joint name="R_WFE" pos="0 0 0" axis="0 -1 0" limited="true" range="-2.0944 2.0944" damping="0.1" />
                                <geom quat="0 0 0 1" type="mesh" rgba="0.953 0.996 0.694 1" mesh="arm_wrist_convex" />
                                <body name="right_endeffector_link" pos="0 0 0.078">
                                    <inertial pos="0.000665605 0.00133386 0.067" quat="-0.0245828 0.702769 -0.0197878 0.710718" mass="1.5" diaginertia="0.00436661 0.00407968 0.00357047" />
                                    <joint name="R_WAA" pos="0 0 0" axis="0 0 1" limited="true" range="-2.96706 2.96706" damping="0.1" />
                                    <geom pos="0.00701592 -0.0199944 0.025" quat="0.707388 0.706825 0 0" type="mesh" rgba="0.953 0.996 0.694 1" mesh="righthandbase" />
                                    <site name="R_WAA"  pos="0 0 0" size=".03 .03 .03" type="ellipsoid" rgba="0.3 0.2 0.1 0.3"/>
                                    <!--<site name="R_WAA" pos="0 0 0" />-->

                                    <body name="R_SMS_link" pos="-0.0433955 -0.00100613 0.0950435" quat="0.508308 0.508699 -0.491147 0.491552">
                                        <inertial pos="0.004 0 0" quat="0.707107 0.707107 0 0" mass="0.1" diaginertia="2.24083e-05 1.85417e-05 1.42833e-05" />
                                        <joint name="R_SMS" pos="0 0 0" axis="0 0 1" limited="true" range="-0.261 0.2618" damping="0.005" />
                                        <geom type="mesh" rgba="0.953 0.996 0.694 1" mesh="finger_base"/>

                                        <body name="R_SMP_link" pos="0 0 0" quat="0.707107 0.707107 0 0">
                                            <inertial pos="0.035 -0.02 0" quat="0.707107 0 0 0.707107" mass="0.1" diaginertia="7.00417e-05 6.68333e-05 2.48083e-05" />
                                            <joint name="R_SMP" pos="0 0 0" axis="0 0 1" limited="true" range="0.087 1.4835" damping="0.005" />
                                            <geom pos="-0.085 0.015 -0.03" quat="0.500398 -0.499602 -0.5 -0.5" type="mesh" rgba="0.953 0.996 0.694 1" mesh="fore_proximalp" />

                                            <body name="R_SMD_link" pos="0.055 0 0">
                                                <inertial pos="0.015 -0.01 0" mass="0.1" diaginertia="3.00333e-05 2.90667e-05 1.40333e-05" />
                                                <joint name="R_SMD" pos="0 0 0" axis="0 0 1" limited="true" range="0.087 1.1345" damping="0.005" />
                                                <geom pos="-0.14 0.015 -0.03" quat="0.505373 -0.494577 -0.504971 -0.494971" type="mesh" rgba="0.953 0.996 0.694 1" mesh="fore_middlep" />
                                                 <body name="R_SME_link" pos="0 0 0">
                                                    <inertial pos="0.015 -0.01 0" mass="0.1" diaginertia="3.00333e-05 2.90667e-05 1.40333e-05" />
                                                     <geom pos="-0.14 0.015 -0.03" quat="0.505373 -0.494577 -0.504971 -0.494971" type="mesh" rgba="0.953 0.996 0.694 1" mesh="fore_distalp" />
                                                 </body>
                                            </body>
                                        </body>
                                    </body>
                                    <body name="R_RIS_link" pos="-0.0168021 0.0025165 0.114044" quat="0.508308 0.508699 -0.491147 0.491552">
                                        <inertial pos="0.004 0 0" quat="0.707107 0.707107 0 0" mass="0.1" diaginertia="2.24083e-05 1.85417e-05 1.42833e-05" />
                                        <joint name="R_RIS" pos="0 0 0" axis="0 0 1" limited="true" range="-0.261 0.2618" damping="0.005" />
                                        <geom type="mesh" rgba="0.953 0.996 0.694 1" mesh="finger_base" />
                                        <body name="R_RIP_link" pos="0 0 0" quat="0.707107 0.707107 0 0">
                                            <inertial pos="0.035 -0.02 0" quat="0.707107 0 0 0.707107" mass="0.1" diaginertia="7.00417e-05 6.68333e-05 2.48083e-05" />
                                            <joint name="R_RIP" pos="0 0 0" axis="0 0 1" limited="true" range="0.087 1.4835" damping="0.005" />
                                            <geom pos="-0.085 0.015 -0.03" quat="0.500398 -0.499602 -0.5 -0.5" type="mesh" rgba="0.953 0.996 0.694 1" mesh="fore_proximalp" />
                                            <body name="R_RID_link" pos="0.055 0 0">
                                                <inertial pos="0.015 -0.01 0" mass="0.1" diaginertia="3.00333e-05 2.90667e-05 1.40333e-05" />
                                                <joint name="R_RID" pos="0 0 0" axis="0 0 1" limited="true" range="0.087 1.1345" damping="0.005" />
                                                <geom pos="-0.14 0.015 -0.03" quat="0.505373 -0.494577 -0.504971 -0.494971" type="mesh" rgba="0.953 0.996 0.694 1" mesh="fore_middlep" />
                                                 <body name="R_RIE_link" pos="0 0 0">
                                                    <inertial pos="0.015 -0.01 0" mass="0.1" diaginertia="3.00333e-05 2.90667e-05 1.40333e-05" />
                                                     <geom pos="-0.14 0.015 -0.03" quat="0.505373 -0.494577 -0.504971 -0.494971" type="mesh" rgba="0.953 0.996 0.694 1" mesh="fore_distalp" />
                                                </body>
                                            </body>
                                        </body>
                                    </body>
                                    <body name="R_MIS_link" pos="0.00979812 0.00253768 0.116744" quat="0.508308 0.508699 -0.491147 0.491552">
                                        <inertial pos="0.004 0 0" quat="0.707107 0.707107 0 0" mass="0.1" diaginertia="2.24083e-05 1.85417e-05 1.42833e-05" />
                                        <joint name="R_MIS" pos="0 0 0" axis="0 0 1" limited="true" range="-0.261 0.2618" damping="0.005" />
                                        <geom type="mesh" rgba="0.953 0.996 0.694 1" mesh="finger_base" />
                                        <body name="R_MIP_link" pos="0 0 0" quat="0.707107 0.707107 0 0">
                                            <inertial pos="0.035 -0.02 0" quat="0.707107 0 0 0.707107" mass="0.1" diaginertia="7.00417e-05 6.68333e-05 2.48083e-05" />
                                            <joint name="R_MIP" pos="0 0 0" axis="0 0 1" limited="true" range="0.087 1.4835" damping="0.005" />
                                            <geom pos="-0.085 0.015 -0.03" quat="0.500398 -0.499602 -0.5 -0.5" type="mesh" rgba="0.953 0.996 0.694 1" mesh="fore_proximalp" />
                                            <body name="R_MID_link" pos="0.055 0 0">
                                                <inertial pos="0.015 -0.01 0" mass="0.1" diaginertia="3.00333e-05 2.90667e-05 1.40333e-05" />
                                                <joint name="R_MID" pos="0 0 0" axis="0 0 1" limited="true" range="0.087 1.1345" damping="0.005" />
                                                <geom pos="-0.14 0.015 -0.03" quat="0.505373 -0.494577 -0.504971 -0.494971" type="mesh" rgba="0.953 0.996 0.694 1" mesh="fore_middlep" />

                                                <body name="R_MIE_link" pos="0 0 0">
                                                    <inertial pos="0.015 -0.01 0" mass="0.1" diaginertia="3.00333e-05 2.90667e-05 1.40333e-05" />
                                                     <geom pos="-0.14 0.015 -0.03" quat="0.505373 -0.494577 -0.504971 -0.494971" type="mesh" rgba="0.953 0.996 0.694 1" mesh="fore_distalp" />
                                                </body>
                                            </body>
                                        </body>
                                    </body>
                                    <body name="R_INS_link" pos="0.0367981 0.00255919 0.108744" quat="0.508308 0.508699 -0.491147 0.491552">
                                        <inertial pos="0.004 0 0" quat="0.707107 0.707107 0 0" mass="0.1" diaginertia="2.24083e-05 1.85417e-05 1.42833e-05" />
                                        <joint name="R_INS" pos="0 0 0" axis="0 0 1" limited="true" range="-0.261 0.2618" damping="0.005" />
                                        <geom type="mesh" rgba="0.953 0.996 0.694 1" mesh="finger_base" />

                                        <body name="R_INP_link" pos="0 0 0" quat="0.707107 0.707107 0 0">
                                            <inertial pos="0.035 -0.02 0" quat="0.707107 0 0 0.707107" mass="0.1" diaginertia="7.00417e-05 6.68333e-05 2.48083e-05" />
                                            <joint name="R_INP" pos="0 0 0" axis="0 0 1" limited="true" range="0.087 1.4835" damping="0.005" />
                                            <geom pos="-0.085 0.015 -0.03" quat="0.500398 -0.499602 -0.5 -0.5" type="mesh" rgba="0.953 0.996 0.694 1" mesh="fore_proximalp" />

                                            <body name="R_IND_link" pos="0.055 0 0">
                                                <inertial pos="0.015 -0.01 0" mass="0.1" diaginertia="3.00333e-05 2.90667e-05 1.40333e-05" />
                                                <joint name="R_IND" pos="0 0 0" axis="0 0 1" limited="true" range="0.087 1.1345" damping="0.005" />
                                                <geom pos="-0.14 0.015 -0.03" quat="0.505373 -0.494577 -0.504971 -0.494971" type="mesh" rgba="0.953 0.996 0.694 1" mesh="fore_middlep" />

                                                <body name="R_INE_link" pos="0 0 0">
                                                    <inertial pos="0.015 -0.01 0" mass="0.1" diaginertia="3.00333e-05 2.90667e-05 1.40333e-05" />
                                                     <geom pos="-0.14 0.015 -0.03" quat="0.505373 -0.494577 -0.504971 -0.494971" type="mesh" rgba="0.953 0.996 0.694 1" mesh="fore_distalp" />
                                                </body>
                                            </body>
                                        </body>
                                    </body>
                                    <body name="R_THS_link" pos="0.0445944 -0.0625336 0.0800446" quat="0.786357 -0.213643 -0.409349 -0.410406">
                                        <inertial pos="0.004 0 0" quat="0.707107 0.707107 0 0" mass="0.1" diaginertia="2.24083e-05 1.85417e-05 1.42833e-05" />
                                        <joint name="R_THS" pos="0 0 0" axis="0 0 1" limited="true" range="-0.261 0.2618" damping="0.005" />
                                        <geom type="mesh" rgba="0.953 0.996 0.694 1" mesh="finger_base" />
                                        <body name="R_THP_link" pos="0 0 0" quat="0.707107 0.707107 0 0">
                                            <inertial pos="0.035 -0.02 0" quat="0.707107 0 0 0.707107" mass="0.1" diaginertia="7.00417e-05 6.68333e-05 2.48083e-05" />
                                            <joint name="R_THP" pos="0 0 0" axis="0 0 1" limited="true" range="0.087 1.4835" damping="0.005" />
                                            <geom pos="-0.085 0.015 -0.03" quat="0.500398 -0.499602 -0.5 -0.5" type="mesh" rgba="0.953 0.996 0.694 1" mesh="fore_proximalp" />
                                            <body name="R_THD_link" pos="0.055 0 0">
                                                <inertial pos="0.015 -0.01 0" mass="0.1" diaginertia="3.00333e-05 2.90667e-05 1.40333e-05" />
                                                <joint name="R_THD" pos="0 0 0" axis="0 0 1" limited="true" range="0.087 1.1345" damping="0.005" />
                                                <geom pos="-0.14 0.015 -0.03" quat="0.505373 -0.494577 -0.504971 -0.494971" type="mesh" rgba="0.953 0.996 0.694 1" mesh="fore_middlep" />
                                                <body name="R_THE_link" pos="0 0 0">
                                                    <inertial pos="0.015 -0.01 0" mass="0.1" diaginertia="3.00333e-05 2.90667e-05 1.40333e-05" />
                                                     <geom pos="-0.14 0.015 -0.03" quat="0.505373 -0.494577 -0.504971 -0.494971" type="mesh" rgba="0.953 0.996 0.694 1" mesh="fore_distalp" />
                                                 </body>
                                            </body>
                                        </body>
                                    </body>
                                </body>
                            </body>
                        </body>
                    </body>
                </body>
            </body>
        </body>
        <body name="L_1_link" pos="-0.055 0.155263 1.5" quat="0.612372 -0.353553 0.612372 0.353554">
            <inertial pos="0 0 0.13" quat="0.707107 0.707107 0 0" mass="1" diaginertia="0.00683333 0.00593333 0.0015" />
            <joint name="L_SFE" pos="0 0 0" axis="0 0 1" limited="true" range="-2.96706 2.96706" damping="0.1" />
            <geom quat="0 0 0 1" type="mesh" rgba="0 0 0.8 1" mesh="arm_segment_a_convex" />
            <body name="L_2_link" pos="0 0 0.2">
                <inertial pos="0 0.06 0.07" quat="0.707107 0.707107 0 0" mass="1" diaginertia="0.00683333 0.00593333 0.0015" />
                <joint name="L_SAA" pos="0 0 0" axis="0 -1 0" limited="true" range="-2.0944 2.0944" damping="0.1" />
                <geom pos="0 0 0.2" quat="0 0 1 0" type="mesh" rgba="0 0 0.8 1" mesh="arm_segment_b_convex" />
                <body name="L_3_link" pos="0 0 0.2">
                    <inertial pos="0 0.06 0.13" quat="0.707107 0.707107 0 0" mass="1" diaginertia="0.00683333 0.00593333 0.0015" />
                    <joint name="L_HR" pos="0 0 0" axis="0 0 1" limited="true" range="-2.96706 2.96706" damping="0.1" />
                    <geom type="mesh" rgba="0 0 0.8 1" mesh="arm_segment_a_convex" />
                    <body name="L_4_link" pos="0 0 0.2">
                        <inertial pos="0 -0.06 0.07" quat="0.707107 0.707107 0 0" mass="1" diaginertia="0.00683333 0.00593333 0.0015" />
                        <joint name="L_EB" pos="0 0 0" axis="0 1 0" limited="true" range="-2.0944 2.0944" damping="0.1" />
                        <geom pos="0 0 0.2" quat="0 -1 0 0" type="mesh" rgba="0 0 0.8 1" mesh="arm_segment_b_convex" />
                        <body name="L_5_link" pos="0 0 0.2">
                            <inertial pos="0 0 0.124" quat="0.707107 0.707107 0 0" mass="1" diaginertia="0.00632533 0.00542533 0.0015" />
                            <joint name="L_WR" pos="0 0 0" axis="0 0 1" limited="true" range="-2.96706 2.96706" damping="0.1" />
                            <geom quat="0 0 0 1" type="mesh" rgba="0 0 0.8 1" mesh="arm_segment_last_convex" />
                            <body name="L_6_link" pos="0 0 0.19">
                                <inertial pos="0 0 0.0625" mass="1" diaginertia="0.00260417 0.00260417 0.00260417" />
                                <joint name="L_WFE" pos="0 0 0" axis="0 -1 0" limited="true" range="-2.0944 2.0944" damping="0.1" />
                                <geom quat="0 0 0 1" type="mesh" rgba="0.953 0.996 0.694 1" mesh="arm_wrist_convex" />
                                <body name="left_endeffector_link" pos="0 0 0.078">
                                    <inertial pos="0.000665605 0.00133386 0.067" quat="-0.0245828 0.702769 -0.0197878 0.710718" mass="1.5" diaginertia="0.00436661 0.00407968 0.00357047" />
                                    <joint name="L_WAA" pos="0 0 0" axis="0 0 1" limited="true" range="-2.0944 2.0944" damping="0.1" />
                                    <geom pos="-0.00698407 -0.0200056 0.025" quat="0.707388 0.706825 0 0" type="mesh" rgba="0.953 0.996 0.694 1" mesh="lefthandbase" />
                                    <site name="L_WAA"  pos="0 0 0" size=".03 .03 .03" type="ellipsoid" rgba="0.3 0.2 0.1 0.3"/>
                                    <!--<site name="L_WAA"  pos="0 0 0" />-->


                                    <body name="L_SMS_link" pos="0.0433971 -0.000937013 0.0950435" quat="0.508308 0.508699 -0.491147 0.491552">
                                        <inertial pos="0.004 0 0" quat="0.707107 0.707107 0 0" mass="0.1" diaginertia="2.24083e-05 1.85417e-05 1.42833e-05" />
                                        <joint name="L_SMS" pos="0 0 0" axis="0 0 1" limited="true" range="-0.261 0.2618" damping="0.005" />
                                        <geom type="mesh" rgba="0.953 0.996 0.694 1" mesh="finger_base" />
                                        <body name="L_SMP_link" pos="0 0 0" quat="0.707107 0.707107 0 0">
                                            <inertial pos="0.035 -0.02 0" quat="0.707107 0 0 0.707107" mass="0.1" diaginertia="7.00417e-05 6.68333e-05 2.48083e-05" />
                                            <joint name="L_SMP" pos="0 0 0" axis="0 0 1" limited="true" range="0.087 1.4835" damping="0.005" />
                                            <geom pos="-0.085 0.015 -0.03" quat="0.500398 -0.499602 -0.5 -0.5" type="mesh" rgba="0.953 0.996 0.694 1" mesh="fore_proximalp" />
                                            <body name="L_SMD_link" pos="0.055 0 0">
                                                <inertial pos="0.015 -0.01 0" mass="0.1" diaginertia="3.00333e-05 2.90667e-05 1.40333e-05" />
                                                <joint name="L_SMD" pos="0 0 0" axis="0 0 1" limited="true" range="0.087 1.1345" damping="0.005" />
                                                <geom pos="-0.14 0.015 -0.03" quat="0.505373 -0.494577 -0.504971 -0.494971" type="mesh" rgba="0.953 0.996 0.694 1" mesh="fore_middlep" />
                                                <body name="L_SME_link" pos="0 0 0">
                                                    <inertial pos="0.015 -0.01 0" mass="0.1" diaginertia="3.00333e-05 2.90667e-05 1.40333e-05" />
                                                    <geom pos="-0.14 0.015 -0.03" quat="0.505373 -0.494577 -0.504971 -0.494971" type="mesh" rgba="0.953 0.996 0.694 1" mesh="fore_distalp" />
                                                </body>
                                            </body>
                                        </body>
                                    </body>
                                    <body name="L_RIS_link" pos="0.0167981 0.00254326 0.114044" quat="0.508308 0.508699 -0.491147 0.491552">
                                        <inertial pos="0.004 0 0" quat="0.707107 0.707107 0 0" mass="0.1" diaginertia="2.24083e-05 1.85417e-05 1.42833e-05" />
                                        <joint name="L_RIS" pos="0 0 0" axis="0 0 1" limited="true" range="-0.261 0.2618" damping="0.005" />
                                        <geom type="mesh" rgba="0.953 0.996 0.694 1" mesh="finger_base" />
                                        <body name="L_RIP_link" pos="0 0 0" quat="0.707107 0.707107 0 0">
                                            <inertial pos="0.035 -0.02 0" quat="0.707107 0 0 0.707107" mass="0.1" diaginertia="7.00417e-05 6.68333e-05 2.48083e-05" />
                                            <joint name="L_RIP" pos="0 0 0" axis="0 0 1" limited="true" range="0.087 1.4835" damping="0.005" />
                                            <geom pos="-0.085 0.015 -0.03" quat="0.500398 -0.499602 -0.5 -0.5" type="mesh" rgba="0.953 0.996 0.694 1" mesh="fore_proximalp" />
                                            <body name="L_RID_link" pos="0.055 0 0">
                                                <inertial pos="0.015 -0.01 0" mass="0.1" diaginertia="3.00333e-05 2.90667e-05 1.40333e-05" />
                                                <joint name="L_RID" pos="0 0 0" axis="0 0 1" limited="true" range="0.087 1.1345" damping="0.005" />
                                                <geom pos="-0.14 0.015 -0.03" quat="0.505373 -0.494577 -0.504971 -0.494971" type="mesh" rgba="0.953 0.996 0.694 1" mesh="fore_middlep" />
                                                 <body name="L_RIE_link" pos="0 0 0">
                                                    <inertial pos="0.015 -0.01 0" mass="0.1" diaginertia="3.00333e-05 2.90667e-05 1.40333e-05" />
                                                     <geom pos="-0.14 0.015 -0.03" quat="0.505373 -0.494577 -0.504971 -0.494971" type="mesh" rgba="0.953 0.996 0.694 1" mesh="fore_distalp" />
                                                 </body>
                                            </body>
                                        </body>
                                    </body>
                                    <body name="L_MIS_link" pos="-0.0100029 0.00369204 0.119" quat="0.508308 0.508699 -0.491147 0.491552">
                                        <inertial pos="0.004 0 0" quat="0.707107 0.707107 0 0" mass="0.1" diaginertia="2.24083e-05 1.85417e-05 1.42833e-05" />
                                        <joint name="L_MIS" pos="0 0 0" axis="0 0 1" limited="true" range="-0.261 0.2618" damping="0.005" />
                                        <geom type="mesh" rgba="0.953 0.996 0.694 1" mesh="finger_base" />
                                        <body name="L_MIP_link" pos="0 0 0" quat="0.707107 0.707107 0 0">
                                            <inertial pos="0.035 -0.02 0" quat="0.707107 0 0 0.707107" mass="0.1" diaginertia="7.00417e-05 6.68333e-05 2.48083e-05" />
                                            <joint name="L_MIP" pos="0 0 0" axis="0 0 1" limited="true" range="0.087 1.4835" damping="0.005" />
                                            <geom pos="-0.085 0.015 -0.03" quat="0.500398 -0.499602 -0.5 -0.5" type="mesh" rgba="0.953 0.996 0.694 1" mesh="fore_proximalp" />
                                            <body name="L_MID_link" pos="0.055 0 0">
                                                <inertial pos="0.015 -0.01 0" mass="0.1" diaginertia="3.00333e-05 2.90667e-05 1.40333e-05" />
                                                <joint name="L_MID" pos="0 0 0" axis="0 0 1" limited="true" range="0.087 1.1345" damping="0.005" />
                                                <geom pos="-0.14 0.015 -0.03" quat="0.505373 -0.494577 -0.504971 -0.494971" type="mesh" rgba="0.953 0.996 0.694 1" mesh="fore_middlep" />
                                                 <body name="L_MIE_link" pos="0 0 0">
                                                    <inertial pos="0.015 -0.01 0" mass="0.1" diaginertia="3.00333e-05 2.90667e-05 1.40333e-05" />
                                                     <geom pos="-0.14 0.015 -0.03" quat="0.505373 -0.494577 -0.504971 -0.494971" type="mesh" rgba="0.953 0.996 0.694 1" mesh="fore_distalp" />
                                                 </body>
                                            </body>
                                        </body>
                                    </body>
                                    <body name="L_INS_link" pos="-0.0368021 0.00250058 0.108744" quat="0.508308 0.508699 -0.491147 0.491552">
                                        <inertial pos="0.004 0 0" quat="0.707107 0.707107 0 0" mass="0.1" diaginertia="2.24083e-05 1.85417e-05 1.42833e-05" />
                                        <joint name="L_INS" pos="0 0 0" axis="0 0 1" limited="true" range="-0.261 0.2618" damping="0.005" />
                                        <geom type="mesh" rgba="0.953 0.996 0.694 1" mesh="finger_base" />
                                        <body name="L_INP_link" pos="0 0 0" quat="0.707107 0.707107 0 0">
                                            <inertial pos="0.035 -0.02 0" quat="0.707107 0 0 0.707107" mass="0.1" diaginertia="7.00417e-05 6.68333e-05 2.48083e-05" />
                                            <joint name="L_INP" pos="0 0 0" axis="0 0 1" limited="true" range="0.087 1.4835" damping="0.005" />
                                            <geom pos="-0.085 0.015 -0.03" quat="0.500398 -0.499602 -0.5 -0.5" type="mesh" rgba="0.953 0.996 0.694 1" mesh="fore_proximalp" />
                                            <body name="L_IND_link" pos="0.055 0 0">
                                                <inertial pos="0.015 -0.01 0" mass="0.1" diaginertia="3.00333e-05 2.90667e-05 1.40333e-05" />
                                                <joint name="L_IND" pos="0 0 0" axis="0 0 1" limited="true" range="0.087 1.1345" damping="0.005" />
                                                <geom pos="-0.14 0.015 -0.03" quat="0.505373 -0.494577 -0.504971 -0.494971" type="mesh" rgba="0.953 0.996 0.694 1" mesh="fore_middlep" />

                                                 <body name="L_INE_link" pos="0 0 0">
                                                    <inertial pos="0.015 -0.01 0" mass="0.1" diaginertia="3.00333e-05 2.90667e-05 1.40333e-05" />
                                                     <geom pos="-0.14 0.015 -0.03" quat="0.505373 -0.494577 -0.504971 -0.494971" type="mesh" rgba="0.953 0.996 0.694 1" mesh="fore_distalp" />
                                                 </body>
                                            </body>
                                        </body>
                                    </body>
                                    <body name="L_THS_link" pos="-0.0444947 -0.0626045 0.0800446" quat="0.411032 -0.409179 -0.213969 -0.78603">
                                        <inertial pos="0.004 0 0" quat="0.707107 0.707107 0 0" mass="0.1" diaginertia="2.24083e-05 1.85417e-05 1.42833e-05" />
                                        <joint name="L_THS" pos="0 0 0" axis="0 0 1" limited="true" range="-0.261 0.2618" damping="0.005" />
                                        <geom type="mesh" rgba="0.953 0.996 0.694 1" mesh="finger_base" />
                                        <body name="L_THP_link" pos="0 0 0" quat="0.707107 0.707107 0 0">
                                            <inertial pos="0.035 -0.02 0" quat="0.707107 0 0 0.707107" mass="0.1" diaginertia="7.00417e-05 6.68333e-05 2.48083e-05" />
                                            <joint name="L_THP" pos="0 0 0" axis="0 0 1" limited="true" range="0.087 1.4835" damping="0.005" />
                                            <geom pos="-0.085 0.015 -0.03" quat="0.500398 -0.499602 -0.5 -0.5" type="mesh" rgba="0.953 0.996 0.694 1" mesh="fore_proximalp" />
                                            <body name="L_THD_link" pos="0.055 0 0">
                                                <inertial pos="0.015 -0.01 0" mass="0.1" diaginertia="3.00333e-05 2.90667e-05 1.40333e-05" />
                                                <joint name="L_THD" pos="0 0 0" axis="0 0 1" limited="true" range="0.087 1.1345" damping="0.005" />
                                                <geom pos="-0.14 0.015 -0.03" quat="0.505373 -0.494577 -0.504971 -0.494971" type="mesh" rgba="0.953 0.996 0.694 1" mesh="fore_middlep" />
                                                <body name="L_THE_link" pos="0 0 0">
                                                    <inertial pos="0.015 -0.01 0" mass="0.1" diaginertia="3.00333e-05 2.90667e-05 1.40333e-05" />
                                                     <geom pos="-0.14 0.015 -0.03" quat="0.505373 -0.494577 -0.504971 -0.494971" type="mesh" rgba="0.953 0.996 0.694 1" mesh="fore_distalp" />
                                                </body>
                                            </body>
                                        </body>
                                    </body>
                                </body>
                            </body>
                        </body>
                    </body>
                </body>
            </body>
        </body>
    </worldbody>
    <sensor>
		<force name="right_endeffector_link_force"	site="R_WAA"/>
		<torque name="right_endeffector_link_torque" site="R_WAA"/>
		<force name="left_endeffector_link_force"	site="L_WAA"/>
		<torque name="left_endeffector_link_torque"	site="L_WAA"/>
	</sensor>
</mujoco>
